
Running tests... 
----------------------------------------------------------------------
 test_Google (AssignmentSecond.TestCaseFirst.TestOpeningGoogle) ... OK (19.006228)s
 test_FacebookTest (AssignmentSecond.LoadYoutube.LaunchFacebook) ... ERROR (15.576599)s

======================================================================
ERROR [15.576599s]: AssignmentSecond.LoadYoutube.LaunchFacebook.test_FacebookTest
----------------------------------------------------------------------
Traceback (most recent call last):
  File "E:\workspace\webAutomationSelenium\AssignmentSecond\LoadYoutube.py", line 21, in test_FacebookTest
    password = driver.find_element_by_id("pas")
  File "C:\Anaconda\Anaconda3\lib\site-packages\selenium\webdriver\remote\webdriver.py", line 360, in find_element_by_id
    return self.find_element(by=By.ID, value=id_)
  File "C:\Anaconda\Anaconda3\lib\site-packages\selenium\webdriver\remote\webdriver.py", line 978, in find_element
    'value': value})['value']
  File "C:\Anaconda\Anaconda3\lib\site-packages\selenium\webdriver\remote\webdriver.py", line 321, in execute
    self.error_handler.check_response(response)
  File "C:\Anaconda\Anaconda3\lib\site-packages\selenium\webdriver\remote\errorhandler.py", line 242, in check_response
    raise exception_class(message, screen, stacktrace)
selenium.common.exceptions.NoSuchElementException: Message: no such element: Unable to locate element: {"method":"css selector","selector":"[id="pas"]"}
  (Session info: chrome=80.0.3987.163)


----------------------------------------------------------------------
Ran 2 tests in 0:00:34

FAILED
 (Errors=1)

Generating HTML reports... 
reports\TestResults_AssignmentSecond.TestCaseFirst.TestOpeningGoogle_2020-04-16_22-03-46.html
reports\TestResults_AssignmentSecond.LoadYoutube.LaunchFacebook_2020-04-16_22-03-46.html
